Workbook

Sheet Дашборд
A1: ProfiMet: по источникам
A2: Период (выберите из списка) | B2: Текущий месяц
A3: Начало | B3: =IF($B$2="Свой период",$E$3,VLOOKUP($B$2,'Списки'!$A$2:$C$25,2,FALSE)) | D3: Свой период: начало | E3: 46235
A4: Конец | B4: =IF($B$2="Свой период",$E$4,MIN(VLOOKUP($B$2,'Списки'!$A$2:$C$25,3,FALSE),MAX('Данные'!$A:$A))) | D4: Свой период: конец | E4: 46314
A5: Курс USD→EUR для Facebook (допущение, можно менять) | B5: 0.8244
A6: Данные есть по | B6: =MAX('Данные'!$A:$A)
A7: Режим подсчёта конверсий и звонков | B7: Наш (60 дней, формы из CRM)
A8: Источник | B8: Цена | C8: Клики | D8: Показы | E8: Цена клика | F8: CTR % | G8: Конверсии | H8: % конверсии | I8: Цена заявки | J8: Звонки | K8: Продажи | L8: % продажи | M8: Цена продажи
A9: Google Ads | B9: =SUMIFS('Данные'!$C:$C,'Данные'!$A:$A,">="&$B$3,'Данные'!$A:$A,"<="&$B$4,'Данные'!$B:$B,$A9) | C9: =SUMIFS('Данные'!$D:$D,'Данные'!$A:$A,">="&$B$3,'Данные'!$A:$A,"<="&$B$4,'Данные'!$B:$B,$A9) | D9: =SUMIFS('Данные'!$E:$E,'Данные'!$A:$A,">="&$B$3,'Данные'!$A:$A,"<="&$B$4,'Данные'!$B:$B,$A9) | E9: =IFERROR(B9/C9,"") | F9: =IFERROR(C9/D9*100,"") | G9: =IF(LEFT($B$7,3)="Как",SUMIFS('Данные'!$I:$I,'Данные'!$A:$A,">="&$B$3,'Данные'!$A:$A,"<="&$B$4,'Данные'!$B:$B,$A9),SUMIFS('Данные'!$F:$F,'Данные'!$A:$A,">="&$B$3,'Данные'!$A:$A,"<="&$B$4,'Данные'!$B:$B,$A9)) | H9: =IFERROR(G9/C9*100,"") | I9: =IFERROR(B9/G9,"") | J9: =IF(LEFT($B$7,3)="Как",SUMIFS('Данные'!$J:$J,'Данные'!$A:$A,">="&$B$3,'Данные'!$A:$A,"<="&$B$4,'Данные'!$B:$B,$A9),SUMIFS('Данные'!$G:$G,'Данные'!$A:$A,">="&$B$3,'Данные'!$A:$A,"<="&$B$4,'Данные'!$B:$B,$A9)) | K9: =SUMIFS('Данные'!$H:$H,'Данные'!$A:$A,">="&$B$3,'Данные'!$A:$A,"<="&$B$4,'Данные'!$B:$B,$A9) | L9: =IFERROR(K9/G9*100,"") | M9: =IFERROR(B9/K9,"")
A10: Facebook | B10: =SUMIFS('Данные'!$C:$C,'Данные'!$A:$A,">="&$B$3,'Данные'!$A:$A,"<="&$B$4,'Данные'!$B:$B,$A10)*$B$5 | C10: =SUMIFS('Данные'!$D:$D,'Данные'!$A:$A,">="&$B$3,'Данные'!$A:$A,"<="&$B$4,'Данные'!$B:$B,$A10) | D10: =SUMIFS('Данные'!$E:$E,'Данные'!$A:$A,">="&$B$3,'Данные'!$A:$A,"<="&$B$4,'Данные'!$B:$B,$A10) | E10: =IFERROR(B10/C10,"") | F10: =IFERROR(C10/D10*100,"") | G10: =IF(LEFT($B$7,3)="Как",SUMIFS('Данные'!$I:$I,'Данные'!$A:$A,">="&$B$3,'Данные'!$A:$A,"<="&$B$4,'Данные'!$B:$B,$A10),SUMIFS('Данные'!$F:$F,'Данные'!$A:$A,">="&$B$3,'Данные'!$A:$A,"<="&$B$4,'Данные'!$B:$B,$A10)) | H10: =IFERROR(G10/C10*100,"") | I10: =IFERROR(B10/G10,"") | J10: =IF(LEFT($B$7,3)="Как",SUMIFS('Данные'!$J:$J,'Данные'!$A:$A,">="&$B$3,'Данные'!$A:$A,"<="&$B$4,'Данные'!$B:$B,$A10),SUMIFS('Данные'!$G:$G,'Данные'!$A:$A,">="&$B$3,'Данные'!$A:$A,"<="&$B$4,'Данные'!$B:$B,$A10)) | K10: =SUMIFS('Данные'!$H:$H,'Данные'!$A:$A,">="&$B$3,'Данные'!$A:$A,"<="&$B$4,'Данные'!$B:$B,$A10) | L10: =IFERROR(K10/G10*100,"") | M10: =IFERROR(B10/K10,"")
A11: Нет метки | B11: — | C11: — | D11: — | E11: — | F11: — | G11: =IF(LEFT($B$7,3)="Как",SUMIFS('Данные'!$I:$I,'Данные'!$A:$A,">="&$B$3,'Данные'!$A:$A,"<="&$B$4,'Данные'!$B:$B,$A11),SUMIFS('Данные'!$F:$F,'Данные'!$A:$A,">="&$B$3,'Данные'!$A:$A,"<="&$B$4,'Данные'!$B:$B,$A11)) | H11: — | I11: — | J11: — | K11: =SUMIFS('Данные'!$H:$H,'Данные'!$A:$A,">="&$B$3,'Данные'!$A:$A,"<="&$B$4,'Данные'!$B:$B,$A11) | L11: =IFERROR(K11/G11*100,"") | M11: —
A12: Телефон | B12: — | C12: — | D12: — | E12: — | F12: — | G12: — | H12: — | I12: — | J12: — | K12: =SUMIFS('Данные'!$H:$H,'Данные'!$A:$A,">="&$B$3,'Данные'!$A:$A,"<="&$B$4,'Данные'!$B:$B,$A12) | L12: — | M12: —
A13: Прочее | B13: — | C13: — | D13: — | E13: — | F13: — | G13: — | H13: — | I13: — | J13: — | K13: =SUMIFS('Данные'!$H:$H,'Данные'!$A:$A,">="&$B$3,'Данные'!$A:$A,"<="&$B$4,'Данные'!$B:$B,$A13) | L13: — | M13: —
A14: Итого | B14: =SUM(B9:B10) | C14: =SUM(C9:C10) | D14: =SUM(D9:D10) | E14: =IFERROR(B14/C14,"") | F14: =IFERROR(C14/D14*100,"") | G14: =SUM(G9:G11) | H14: =IFERROR(G14/C14*100,"") | I14: =IFERROR(B14/G14,"") | J14: =SUM(J9:J10) | K14: =SUM(K9:K13) | L14: =IFERROR(K14/G14*100,"") | M14: =IFERROR(B14/K14,"")
A16: =IF(LEFT($B$7,3)="Как","Режим «как у клиента»: звонки — первый звонок номера за всю историю Ringostat; формы — сеансы GA4 form_submit по источнику сеанса; Телефон и Прочее без конверсий. Продажи — по нашему правилу (выгрузка CRM) в обоих режимах.","Телефон: новых обращений "&SUMIFS('Данные'!$F:$F,'Данные'!$A:$A,">="&$B$3,'Данные'!$A:$A,"<="&$B$4,'Данные'!$B:$B,$A12)&" (из них звонков "&SUMIFS('Данные'!$G:$G,'Данные'!$A:$A,">="&$B$3,'Данные'!$A:$A,"<="&$B$4,'Данные'!$B:$B,$A12)&") — в «Конверсии» и «Звонки» не включены")
A17: =IF(LEFT($B$7,3)="Как","","Нет метки: из "&G11&" конверсий звонков "&SUMIFS('Данные'!$G:$G,'Данные'!$A:$A,">="&$B$3,'Данные'!$A:$A,"<="&$B$4,'Данные'!$B:$B,$A11)&" — в колонке «Звонки» не показаны")
A18: =IF(LEFT($B$7,3)="Как","","Прочее: новых обращений "&SUMIFS('Данные'!$F:$F,'Данные'!$A:$A,">="&$B$3,'Данные'!$A:$A,"<="&$B$4,'Данные'!$B:$B,$A13)&" — в «Конверсии» и «Звонки» не включены")

Sheet Данные
A1: Дата | B1: Источник | C1: Цена (Google — €, Facebook — $ как в BigQuery) | D1: Клики | E1: Показы | F1: Конверсии (наш режим: новые обращения CRM) | G1: из них звонки | H1: Продажи | I1: Конверсии (как у клиента: звонки + формы GA4) | J1: из них звонки (первый звонок за всю историю)
A2: 46235 | B2: Google Ads | C2: 0 | D2: 0 | E2: 0 | F2: 0 | G2: 0 | H2: 0 | I2: 0 | J2: 0
A3: 46235 | B3: Facebook | C3: 0 | D3: 0 | E3: 0 | F3: 0 | G3: 0 | H3: 0 | I3: 0 | J3: 0
A4: 46235 | B4: Нет метки | F4: 0 | G4: 0 | H4: 0 | I4: 0 | J4: 0
A5: 46235 | B5: Телефон | F5: 1 | G5: 1 | H5: 0 | I5: 0 | J5: 0
A6: 46235 | B6: Прочее | F6: 0 | G6: 0 | H6: 0 | I6: 0 | J6: 0
A7: 46236 | B7: Google Ads | C7: 0 | D7: 0 | E7: 0 | F7: 0 | G7: 0 | H7: 0 | I7: 0 | J7: 0
A8: 46236 | B8: Facebook | C8: 0 | D8: 0 | E8: 0 | F8: 0 | G8: 0 | H8: 0 | I8: 0 | J8: 0
A9: 46236 | B9: Нет метки | F9: 1 | G9: 1 | H9: 0 | I9: 0 | J9: 0
A10: 46236 | B10: Телефон | F10: 0 | G10: 0 | H10: 0 | I10: 0 | J10: 0
A11: 46236 | B11: Прочее | F11: 0 | G11: 0 | H11: 0 | I11: 0 | J11: 0
A12: 46237 | B12: Google Ads | C12: 38.000965 | D12: 73 | E12: 604 | F12: 1 | G12: 1 | H12: 0 | I12: 2 | J12: 1
A13: 46237 | B13: Facebook | C13: 15.534626 | D13: 177 | E13: 3545 | F13: 1 | G13: 1 | H13: 0 | I13: 1 | J13: 1
A14: 46237 | B14: Нет метки | F14: 3 | G14: 3 | H14: 0 | I14: 0 | J14: 0
A15: 46237 | B15: Телефон | F15: 8 | G15: 8 | H15: 0 | I15: 0 | J15: 0
A16: 46237 | B16: Прочее | F16: 0 | G16: 0 | H16: 0 | I16: 0 | J16: 0
A17: 46238 | B17: Google Ads | C17: 50.978204 | D17: 97 | E17: 913 | F17: 3 | G17: 3 | H17: 1 | I17: 2 | J17: 2
A18: 46238 | B18: Facebook | C18: 20.822715 | D18: 245 | E18: 4862 | F18: 0 | G18: 0 | H18: 0 | I18: 0 | J18: 0
A19: 46238 | B19: Нет метки | F19: 0 | G19: 0 | H19: 0 | I19: 0 | J19: 0
A20: 46238 | B20: Телефон | F20: 4 | G20: 4 | H20: 0 | I20: 0 | J20: 0
A21: 46238 | B21: Прочее | F21: 0 | G21: 0 | H21: 0 | I21: 0 | J21: 0
A22: 46239 | B22: Google Ads | C22: 37.936247 | D22: 177 | E22: 8964 | F22: 0 | G22: 0 | H22: 1 | I22: 0 | J22: 0
A23: 46239 | B23: Facebook | C23: 28.839335 | D23: 405 | E23: 10449 | F23: 1 | G23: 0 | H23: 1 | I23: 1 | J23: 0
A24: 46239 | B24: Нет метки | F24: 1 | G24: 1 | H24: 0 | I24: 0 | J24: 0
A25: 46239 | B25: Телефон | F25: 5 | G25: 5 | H25: 0 | I25: 0 | J25: 0
A26: 46239 | B26: Прочее | F26: 0 | G26: 0 | H26: 0 | I26: 0 | J26: 0
A27: 46240 | B27: Google Ads | C27: 50.772604 | D27: 490 | E27: 13327 | F27: 1 | G27: 1 | H27: 0 | I27: 2 | J27: 2
A28: 46240 | B28: Facebook | C28: 29.030471 | D28: 483 | E28: 11529 | F28: 1 | G28: 1 | H28: 0 | I28: 1 | J28: 1
A29: 46240 | B29: Нет метки | F29: 0 | G29: 0 | H29: 0 | I29: 0 | J29: 0
A30: 46240 | B30: Телефон | F30: 5 | G30: 5 | H30: 0 | I30: 0 | J30: 0
A31: 46240 | B31: Прочее | F31: 0 | G31: 0 | H31: 0 | I31: 0 | J31: 0
A32: 46241 | B32: Google Ads | C32: 30.01218 | D32: 205 | E32: 3820 | F32: 0 | G32: 0 | H32: 2 | I32: 0 | J32: 0
A33: 46241 | B33: Facebook | C33: 27.063712 | D33: 521 | E33: 11522 | F33: 1 | G33: 1 | H33: 1 | I33: 1 | J33: 1
A34: 46241 | B34: Нет метки | F34: 2 | G34: 2 | H34: 1 | I34: 1 | J34: 0
A35: 46241 | B35: Телефон | F35: 2 | G35: 2 | H35: 0 | I35: 0 | J35: 0
A36: 46241 | B36: Прочее | F36: 6 | G36: 0 | H36: 0 | I36: 0 | J36: 0
A37: 46242 | B37: Google Ads | C37: 9.887985 | D37: 29 | E37: 389 | F37: 0 | G37: 0 | H37: 0 | I37: 0 | J37: 0
A38: 46242 | B38: Facebook | C38: 27.554017 | D38: 523 | E38: 9844 | F38: 1 | G38: 1 | H38: 0 | I38: 1 | J38: 1
A39: 46242 | B39: Нет метки | F39: 0 | G39: 0 | H39: 0 | I39: 0 | J39: 0
A40: 46242 | B40: Телефон | F40: 0 | G40: 0 | H40: 0 | I40: 0 | J40: 0
...

Sheet Списки
A1: Период | B1: Начало | C1: Конец
A2: Текущий месяц | B2: =DATE(YEAR(TODAY()),MONTH(TODAY()),1) | C2: =EOMONTH(TODAY(),0)
A3: Прошлый месяц | B3: =EOMONTH(TODAY(),-2)+1 | C3: =EOMONTH(TODAY(),-1)
A4: Текущая неделя | B4: =TODAY()-WEEKDAY(TODAY(),2)+1 | C4: =B4+6
A5: Прошлая неделя | B5: =TODAY()-WEEKDAY(TODAY(),2)-6 | C5: =B5+6
A6: Последние 7 дней | B6: =TODAY()-7 | C6: =TODAY()-1
A7: Последние 30 дней | B7: =TODAY()-30 | C7: =TODAY()-1
A8: Весь период (01.08.2026–19.10.2026) | B8: 46235 | C8: 46314
A9: Август 2026 | B9: 46235 | C9: 46265
A10: Сентябрь 2026 | B10: 46266 | C10: 46295
A11: Октябрь 2026 | B11: 46296 | C11: 46314
A12: Неделя 01.08–02.08.2026 | B12: 46235 | C12: 46236
A13: Неделя 03.08–09.08.2026 | B13: 46237 | C13: 46243
A14: Неделя 10.08–16.08.2026 | B14: 46244 | C14: 46250
A15: Неделя 17.08–23.08.2026 | B15: 46251 | C15: 46257
A16: Неделя 24.08–30.08.2026 | B16: 46258 | C16: 46264
A17: Неделя 31.08–06.09.2026 | B17: 46265 | C17: 46271
A18: Неделя 07.09–13.09.2026 | B18: 46272 | C18: 46278
A19: Неделя 14.09–20.09.2026 | B19: 46279 | C19: 46285
... A24: Неделя 19.10–19.10.2026 | B24: 46314 | C24: 46314
A25: Свой период

Sheet Как считается
A1: Цена, клики, показы: Google Ads — из Google Ads API по аккаунту целиком; Facebook — из BigQuery adwhite.fb_stats_profimet (там доллары, в евро пересчитано по курсу из параметра --usd-eur).
A2: Конверсии: новые обращения (звонки и формы) из выгрузки CRM по правилу 60 дней — обращение новое, если у этого номера не было засчитанного нового обращения за последние 60 дней (окно от последнего засчитанного, повторы окно не продлевают).
A3: Звонки: из конверсий те, что звонки (показаны только у Google Ads и Facebook).
A4: Продажи: проданные заказы (в выгрузке есть «Дата продажи» в периоде); источник продажи — источник первого обращения этого номера за 60 дней до первой строки заказа. Количества товара в выгрузке нет, поэтому это заказы, а не единицы.
A5: % конверсии = Конверсии ÷ Клики; Цена заявки = Цена ÷ Конверсии; % продажи = Продажи ÷ Конверсии; Цена продажи = Цена ÷ Продажи; CTR = Клики ÷ Показы; Цена клика = Цена ÷ Клики. «Итого»: цена, клики, показы — Google + Facebook; конверсии и продажи — по всем строкам.
A6: Курс USD→EUR для Facebook — ячейка B5 листа «Дашборд» (допущение; в BigQuery расход хранится в долларах).
A7: Режим B7: «Наш» — конверсии и звонки по нашему правилу 60 дней из выгрузки CRM; «Как у клиента» — звонки: первый звонок номера за всю историю Ringostat (входящие, отслеживаемые каналы), формы: сеансы GA4 form_submit по источнику сеанса (google / cpc → Google Ads, facebook* → Facebook, остальное → Нет метки); подтверждено на двух периодах скринов клиента 2026-10-20. Продажи в обоих режимах одинаковые (наше правило).
A8: Период выбирается в ячейке B2 листа «Дашборд»; для «Свой период» даты вводятся в E3 и E4. «Текущий месяц» и «Текущая неделя» считаются от сегодняшней даты, но данных нет позже даты, указанной в B6 (данные обновляются повторным запуском скрипта profimet_sources_dashboard.py).
