Workbook

Sheet Дашборд
A1: ProfiMet: по источникам
A2: Период (выберите из списка) | B2: Текущий месяц
A3: Начало | B3: =IF($B$2="Свой период",$E$3,VLOOKUP($B$2,'Списки'!$A$2:$C$14,2,FALSE)) | D3: Свой период: начало | E3: 46296
A4: Конец | B4: =IF($B$2="Свой период",$E$4,MIN(VLOOKUP($B$2,'Списки'!$A$2:$C$14,3,FALSE),MAX('Данные'!$A:$A))) | D4: Свой период: конец | E4: 46315
A5: Курс USD→EUR для Facebook (допущение, можно менять) | B5: 0.8244
A6: Данные есть по | B6: =MAX('Данные'!$A:$A)
A7: Режим подсчёта конверсий и звонков | B7: Наш (60 дней, формы из CRM)
A8: Источник | B8: Цена | C8: Клики | D8: Показы | E8: Цена клика | F8: CTR % | G8: Конверсии | H8: % конверсии | I8: Цена заявки | J8: Звонки | K8: Продажи | L8: % продажи | M8: Цена продажи
A9: Google Ads | B9: =SUMIFS('Данные'!$C:$C,'Данные'!$A:$A,">="&$B$3,'Данные'!$A:$A,"<="&$B$4,'Данные'!$B:$B,$A9) | C9: =SUMIFS('Данные'!$D:$D,'Данные'!$A:$A,">="&$B$3,'Данные'!$A:$A,"<="&$B$4,'Данные'!$B:$B,$A9) | D9: =SUMIFS('Данные'!$E:$E,'Данные'!$A:$A,">="&$B$3,'Данные'!$A:$A,"<="&$B$4,'Данные'!$B:$B,$A9) | E9: =IFERROR(B9/C9,"") | F9: =IFERROR(C9/D9*100,"") | G9: =IF(LEFT($B$7,3)="Как",SUMIFS('Данные'!$I:$I,'Данные'!$A:$A,">="&$B$3,'Данные'!$A:$A,"<="&$B$4,'Данные'!$B:$B,$A9),SUMIFS('Данные'!$F:$F,'Данные'!$A:$A,">="&$B$3,'Данные'!$A:$A,"<="&$B$4,'Данные'!$B:$B,$A9)) | H9: =IFERROR(G9/C9*100,"") | I9: =IFERROR(B9/G9,"") | J9: =IF(LEFT($B$7,3)="Как",SUMIFS('Данные'!$J:$J,'Данные'!$A:$A,">="&$B$3,'Данные'!$A:$A,"<="&$B$4,'Данные'!$B:$B,$A9),SUMIFS('Данные'!$G:$G,'Данные'!$A:$A,">="&$B$3,'Данные'!$A:$A,"<="&$B$4,'Данные'!$B:$B,$A9)) | K9: =IF(LEFT($B$7,3)="Как",SUMIFS('Данные'!$K:$K,'Данные'!$A:$A,">="&$B$3,'Данные'!$A:$A,"<="&$B$4,'Данные'!$B:$B,$A9),SUMIFS('Данные'!$H:$H,'Данные'!$A:$A,">="&$B$3,'Данные'!$A:$A,"<="&$B$4,'Данные'!$B:$B,$A9)) | L9: =IFERROR(K9/G9*100,"") | M9: =IFERROR(B9/K9,"")
A10: Facebook | B10: =SUMIFS('Данные'!$C:$C,'Данные'!$A:$A,">="&$B$3,'Данные'!$A:$A,"<="&$B$4,'Данные'!$B:$B,$A10)*$B$5 | C10: =SUMIFS('Данные'!$D:$D,'Данные'!$A:$A,">="&$B$3,'Данные'!$A:$A,"<="&$B$4,'Данные'!$B:$B,$A10) | D10: =SUMIFS('Данные'!$E:$E,'Данные'!$A:$A,">="&$B$3,'Данные'!$A:$A,"<="&$B$4,'Данные'!$B:$B,$A10) | E10: =IFERROR(B10/C10,"") | F10: =IFERROR(C10/D10*100,"") | G10: =IF(LEFT($B$7,3)="Как",SUMIFS('Данные'!$I:$I,'Данные'!$A:$A,">="&$B$3,'Данные'!$A:$A,"<="&$B$4,'Данные'!$B:$B,$A10),SUMIFS('Данные'!$F:$F,'Данные'!$A:$A,">="&$B$3,'Данные'!$A:$A,"<="&$B$4,'Данные'!$B:$B,$A10)) | H10: =IFERROR(G10/C10*100,"") | I10: =IFERROR(B10/G10,"") | J10: =IF(LEFT($B$7,3)="Как",SUMIFS('Данные'!$J:$J,'Данные'!$A:$A,">="&$B$3,'Данные'!$A:$A,"<="&$B$4,'Данные'!$B:$B,$A10),SUMIFS('Данные'!$G:$G,'Данные'!$A:$A,">="&$B$3,'Данные'!$A:$A,"<="&$B$4,'Данные'!$B:$B,$A10)) | K10: =IF(LEFT($B$7,3)="Как",SUMIFS('Данные'!$K:$K,'Данные'!$A:$A,">="&$B$3,'Данные'!$A:$A,"<="&$B$4,'Данные'!$B:$B,$A10),SUMIFS('Данные'!$H:$H,'Данные'!$A:$A,">="&$B$3,'Данные'!$A:$A,"<="&$B$4,'Данные'!$B:$B,$A10)) | L10: =IFERROR(K10/G10*100,"") | M10: =IFERROR(B10/K10,"")
A11: Нет метки | B11: — | C11: — | D11: — | E11: — | F11: — | G11: =IF(LEFT($B$7,3)="Как",SUMIFS('Данные'!$I:$I,'Данные'!$A:$A,">="&$B$3,'Данные'!$A:$A,"<="&$B$4,'Данные'!$B:$B,$A11),SUMIFS('Данные'!$F:$F,'Данные'!$A:$A,">="&$B$3,'Данные'!$A:$A,"<="&$B$4,'Данные'!$B:$B,$A11)) | H11: — | I11: — | J11: — | K11: =IF(LEFT($B$7,3)="Как",SUMIFS('Данные'!$K:$K,'Данные'!$A:$A,">="&$B$3,'Данные'!$A:$A,"<="&$B$4,'Данные'!$B:$B,$A11),SUMIFS('Данные'!$H:$H,'Данные'!$A:$A,">="&$B$3,'Данные'!$A:$A,"<="&$B$4,'Данные'!$B:$B,$A11)) | L11: =IFERROR(K11/G11*100,"") | M11: —
A12: Телефон | B12: — | C12: — | D12: — | E12: — | F12: — | G12: — | H12: — | I12: — | J12: — | K12: =IF(LEFT($B$7,3)="Как",SUMIFS('Данные'!$K:$K,'Данные'!$A:$A,">="&$B$3,'Данные'!$A:$A,"<="&$B$4,'Данные'!$B:$B,$A12),SUMIFS('Данные'!$H:$H,'Данные'!$A:$A,">="&$B$3,'Данные'!$A:$A,"<="&$B$4,'Данные'!$B:$B,$A12)) | L12: — | M12: —
A13: Прочее | B13: — | C13: — | D13: — | E13: — | F13: — | G13: — | H13: — | I13: — | J13: — | K13: =IF(LEFT($B$7,3)="Как",SUMIFS('Данные'!$K:$K,'Данные'!$A:$A,">="&$B$3,'Данные'!$A:$A,"<="&$B$4,'Данные'!$B:$B,$A13),SUMIFS('Данные'!$H:$H,'Данные'!$A:$A,">="&$B$3,'Данные'!$A:$A,"<="&$B$4,'Данные'!$B:$B,$A13)) | L13: — | M13: —
A14: Итого | B14: =SUM(B9:B10) | C14: =SUM(C9:C10) | D14: =SUM(D9:D10) | E14: =IFERROR(B14/C14,"") | F14: =IFERROR(C14/D14*100,"") | G14: =SUM(G9:G11) | H14: =IFERROR(G14/C14*100,"") | I14: =IFERROR(B14/G14,"") | J14: =SUM(J9:J10) | K14: =SUM(K9:K13) | L14: =IFERROR(K14/G14*100,"") | M14: =IFERROR(B14/K14,"")
A16: =IF(LEFT($B$7,3)="Как","Режим «как у клиента»: звонки — первый звонок номера за всю историю Ringostat; формы — сеансы GA4 form_submit по источнику сеанса; Телефон и Прочее без конверсий. Продажи — по правилу клиента: источник из формы заказа, иначе «Телефон»; заказы на листе «Заказы по схеме клиента», расхождения на листе «Расхождения».","Телефон: новых обращений "&SUMIFS('Данные'!$F:$F,'Данные'!$A:$A,">="&$B$3,'Данные'!$A:$A,"<="&$B$4,'Данные'!$B:$B,$A12)&" (из них звонков "&SUMIFS('Данные'!$G:$G,'Данные'!$A:$A,">="&$B$3,'Данные'!$A:$A,"<="&$B$4,'Данные'!$B:$B,$A12)&") — в «Конверсии» и «Звонки» не включены")
A17: =IF(LEFT($B$7,3)="Как","","Нет метки: из "&G11&" конверсий звонков "&SUMIFS('Данные'!$G:$G,'Данные'!$A:$A,">="&$B$3,'Данные'!$A:$A,"<="&$B$4,'Данные'!$B:$B,$A11)&" — в колонке «Звонки» не показаны")
A18: =IF(LEFT($B$7,3)="Как","","Прочее: новых обращений "&SUMIFS('Данные'!$F:$F,'Данные'!$A:$A,">="&$B$3,'Данные'!$A:$A,"<="&$B$4,'Данные'!$B:$B,$A13)&" — в «Конверсии» и «Звонки» не включены")

Sheet Данные
A1: Дата | B1: Источник | C1: Цена (Google — €, Facebook — $ как в BigQuery) | D1: Клики | E1: Показы | F1: Конверсии (наш режим: новые обращения CRM) | G1: из них звонки | H1: Продажи | I1: Конверсии (как у клиента: звонки + формы GA4) | J1: из них звонки (первый звонок за всю историю) | K1: Продажи (как у клиента: по правилу клиента, количество товара)
A2: 46296 | B2: Google Ads | C2: 472.56327 | D2: 5434 | E2: 265054 | F2: 12 | G2: 11 | H2: 2 | I2: 7 | J2: 7 | K2: 1
A3: 46296 | B3: Facebook | C3: 35.174515 | D3: 308 | E3: 7925 | F3: 0 | G3: 0 | H3: 0 | I3: 0 | J3: 0 | K3: 0
A4: 46296 | B4: Нет метки | F4: 0 | G4: 0 | H4: 2 | I4: 0 | J4: 0 | K4: 0
A5: 46296 | B5: Телефон | F5: 7 | G5: 7 | H5: 2 | I5: 0 | J5: 0 | K5: 0
A6: 46296 | B6: Прочее | F6: 0 | G6: 0 | H6: 0 | I6: 0 | J6: 0 | K6: 0
A7: 46297 | B7: Google Ads | C7: 142.88461 | D7: 1071 | E7: 38318 | F7: 5 | G7: 5 | H7: 1 | I7: 5 | J7: 4 | K7: 0
A8: 46297 | B8: Facebook | C8: 31.836565 | D8: 338 | E8: 6146 | F8: 1 | G8: 1 | H8: 1 | I8: 1 | J8: 1 | K8: 0
A9: 46297 | B9: Нет метки | F9: 1 | G9: 0 | H9: 0 | I9: 0 | J9: 0 | K9: 0
A10: 46297 | B10: Телефон | F10: 3 | G10: 3 | H10: 0 | I10: 0 | J10: 0 | K10: 3
A11: 46297 | B11: Прочее | F11: 0 | G11: 0 | H11: 0 | I11: 0 | J11: 0 | K11: 0
A12: 46298 | B12: Google Ads | C12: 5.348426 | D12: 8 | E12: 28 | F12: 0 | G12: 0 | H12: 0 | I12: 0 | J12: 0 | K12: 0
A13: 46298 | B13: Facebook | C13: 31.268698 | D13: 345 | E13: 6544 | F13: 0 | G13: 0 | H13: 0 | I13: 0 | J13: 0 | K13: 0
A14: 46298 | B14: Нет метки | F14: 0 | G14: 0 | H14: 0 | I14: 0 | J14: 0 | K14: 0
A15: 46298 | B15: Телефон | F15: 0 | G15: 0 | H15: 0 | I15: 0 | J15: 0 | K15: 0
A16: 46298 | B16: Прочее | F16: 0 | G16: 0 | H16: 0 | I16: 0 | J16: 0 | K16: 0
A17: 46299 | B17: Google Ads | C17: 0 | D17: 0 | E17: 0 | F17: 0 | G17: 0 | H17: 0 | I17: 0 | J17: 0 | K17: 0
A18: 46299 | B18: Facebook | C18: 40.806094 | D18: 520 | E18: 8994 | F18: 1 | G18: 1 | H18: 0 | I18: 2 | J18: 1 | K18: 0
A19: 46299 | B19: Нет метки | F19: 1 | G19: 0 | H19: 0 | I19: 0 | J19: 0 | K19: 1
A20: 46299 | B20: Телефон | F20: 0 | G20: 0 | H20: 0 | I20: 0 | J20: 0 | K20: 0
A21: 46299 | B21: Прочее | F21: 0 | G21: 0 | H21: 0 | I21: 0 | J21: 0 | K21: 0
A22: 46300 | B22: Google Ads | C22: 106.02169 | D22: 418 | E22: 5593 | F22: 5 | G22: 5 | H22: 6 | I22: 7 | J22: 5 | K22: 1
A23: 46300 | B23: Facebook | C23: 34.01385 | D23: 424 | E23: 7257 | F23: 2 | G23: 0 | H23: 0 | I23: 2 | J23: 0 | K23: 0
A24: 46300 | B24: Нет метки | F24: 6 | G24: 3 | H24: 4 | I24: 0 | J24: 0 | K24: 2
A25: 46300 | B25: Телефон | F25: 22 | G25: 22 | H25: 6 | I25: 0 | J25: 0 | K25: 8
A26: 46300 | B26: Прочее | F26: 0 | G26: 0 | H26: 0 | I26: 0 | J26: 0 | K26: 0
A27: 46301 | B27: Google Ads | C27: 83.565941 | D27: 233 | E27: 2308 | F27: 2 | G27: 1 | H27: 1 | I27: 3 | J27: 2 | K27: 1
A28: 46301 | B28: Facebook | C28: 35.221607 | D28: 334 | E28: 7726 | F28: 0 | G28: 0 | H28: 0 | I28: 0 | J28: 0 | K28: 0
A29: 46301 | B29: Нет метки | F29: 2 | G29: 1 | H29: 2 | I29: 1 | J29: 0 | K29: 1
A30: 46301 | B30: Телефон | F30: 6 | G30: 6 | H30: 4 | I30: 0 | J30: 0 | K30: 2
A31: 46301 | B31: Прочее | F31: 0 | G31: 0 | H31: 0 | I31: 0 | J31: 0 | K31: 0
A32: 46302 | B32: Google Ads | C32: 150.14732 | D32: 482 | E32: 8318 | F32: 3 | G32: 3 | H32: 1 | I32: 4 | J32: 3 | K32: 0
A33: 46302 | B33: Facebook | C33: 24.817175 | D33: 259 | E33: 5335 | F33: 1 | G33: 1 | H33: 0 | I33: 1 | J33: 1 | K33: 0
A34: 46302 | B34: Нет метки | F34: 1 | G34: 0 | H34: 3 | I34: 0 | J34: 0 | K34: 1
A35: 46302 | B35: Телефон | F35: 12 | G35: 12 | H35: 1 | I35: 0 | J35: 0 | K35: 0
A36: 46302 | B36: Прочее | F36: 0 | G36: 0 | H36: 0 | I36: 0 | J36: 0 | K36: 0
A37: 46303 | B37: Google Ads | C37: 236.3385 | D37: 1112 | E37: 26985 | F37: 7 | G37: 6 | H37: 4 | I37: 8 | J37: 6 | K37: 1
A38: 46303 | B38: Facebook | C38: 23.980609 | D38: 235 | E38: 4194 | F38: 1 | G38: 1 | H38: 1 | I38: 2 | J38: 1 | K38: 0
A39: 46303 | B39: Нет метки | F39: 2 | G39: 1 | H39: 1 | I39: 0 | J39: 0 | K39: 0
A40: 46303 | B40: Телефон | F40: 13 | G40: 13 | H40: 1 | I40: 0 | J40: 0 | K40: 5
...

Sheet Списки
A1: Период | B1: Начало | C1: Конец
A2: Текущий месяц | B2: =DATE(YEAR(TODAY()),MONTH(TODAY()),1) | C2: =EOMONTH(TODAY(),0)
A3: Прошлый месяц | B3: =EOMONTH(TODAY(),-2)+1 | C3: =EOMONTH(TODAY(),-1)
A4: Текущая неделя | B4: =TODAY()-WEEKDAY(TODAY(),2)+1 | C4: =B4+6
A5: Прошлая неделя | B5: =TODAY()-WEEKDAY(TODAY(),2)-6 | C5: =B5+6
A6: Последние 7 дней | B6: =TODAY()-7 | C6: =TODAY()-1
A7: Последние 30 дней | B7: =TODAY()-30 | C7: =TODAY()-1
A8: Весь период (01.10.2026–20.10.2026) | B8: 46296 | C8: 46315
A9: Октябрь 2026 | B9: 46296 | C9: 46315
A10: Неделя 01.10–04.10.2026 | B10: 46296 | C10: 46299
A11: Неделя 05.10–11.10.2026 | B11: 46300 | C11: 46306
A12: Неделя 12.10–18.10.2026 | B12: 46307 | C12: 46313
A13: Неделя 19.10–20.10.2026 | B13: 46314 | C13: 46315
A14: Свой период

Sheet Как считается
A1: Цена, клики, показы: Google Ads — из Google Ads API по аккаунту целиком; Facebook — из BigQuery adwhite.fb_stats_profimet (там доллары, в евро пересчитано по курсу из параметра --usd-eur).
A2: Конверсии: новые обращения (звонки и формы) из выгрузки CRM по правилу 60 дней — обращение новое, если у этого номера не было засчитанного нового обращения за последние 60 дней (окно от последнего засчитанного, повторы окно не продлевают).
A3: Звонки: из конверсий те, что звонки (показаны только у Google Ads и Facebook).
A4: Продажи: проданные заказы (в выгрузке есть «Дата продажи» в периоде); источник продажи — источник первого обращения этого номера за 60 дней до первой строки заказа. Количества товара в выгрузке нет, поэтому это заказы, а не единицы.
A5: % конверсии = Конверсии ÷ Клики; Цена заявки = Цена ÷ Конверсии; % продажи = Продажи ÷ Конверсии; Цена продажи = Цена ÷ Продажи; CTR = Клики ÷ Показы; Цена клика = Цена ÷ Клики. «Итого»: цена, клики, показы — Google + Facebook; конверсии и продажи — по всем строкам.
A6: Курс USD→EUR для Facebook — ячейка B5 листа «Дашборд» (допущение; в BigQuery расход хранится в долларах).
A7: Режим B7: «Наш» — конверсии и звонки по нашему правилу 60 дней из выгрузки CRM; «Как у клиента» — звонки: первый звонок номера за всю историю Ringostat (входящие, отслеживаемые каналы), формы: сеансы GA4 form_submit по источнику сеанса (google / cpc → Google Ads, facebook* → Facebook, остальное → Нет метки); подтверждено на двух периодах скринов клиента 2026-10-20. Продажи в режиме «Как у клиента»: источник заказа по правилу клиента (есть форма → источник формы, нет формы → «Телефон»), дата заказа = дата первой строки (UTC), количество товара из списка клиента, где он есть, иначе 1; в режиме «Наш» продажи по первому обращению за 60 дней.
A8: Лист «Заказы по схеме клиента»: правила, которые использует клиент (как мы их поняли), применены к данным нашей выгрузки CRM. Поэтому в нём есть заказы, которых нет в дашборде клиента, и нет заказов клиента, которых нет в выгрузке CRM; все такие случаи с причинами на листе «Расхождения».
A9: Период выбирается в ячейке B2 листа «Дашборд»; для «Свой период» даты вводятся в E3 и E4. «Текущий месяц» и «Текущая неделя» считаются от сегодняшней даты, но данных нет позже даты, указанной в B6 (данные обновляются повторным запуском скрипта profimet_sources_dashboard.py).

Sheet Заказы по схеме клиента
A1: Дата заказа (оценка) UTC | B1: Заказ | C1: Телефон | D1: Товар | E1: Кол-во | F1: Источник по правилу клиента | G1: Источник заказа в дашборде клиента | H1: Есть у клиента | I1: Площадка | J1: Автор
A2: 2026-10-20 16:47 | B2: 13207395 | C2: +48797455191 | D2: Tunel 3x6m / 40x20mm | E2: 1 | F2: Нет метки | G2: Нет метки | H2: да | I2: Tilda | J2: script_Tilda_MOCNA
A3: 2026-10-20 12:20 | B3: 11293836 | C3: +48887214683 | D3: Tunel 3x6m / 40x20mm | E3: 1 | F3: Google Ads | G3: Google Ads | H3: да | I3: Tilda | J3: script_Tilda_MOCNA
A4: 2026-10-20 11:13 | B4: 17330065 | C4: +48668003559 | D4: Domek 2.5x6m / 40x20mm 6mm | E4: 1 | F4: Google Ads | G4: Google Ads | H4: да | I4: Tilda | J4: script_Tilda_MOCNA
A5: 2026-10-20 09:38 | B5: 72931963 | C5: +48724458796 | D5: Domek 2.5x4m / 40x20mm 6mm | E5: 1 | F5: Телефон | G5: Телефон | H5: да | I5: Tilda | J5: s.mocnaszklarnia@profimetpl.com
A6: 2026-10-20 09:30 | B6: 70182e9e | C6: +48503861418 | D6: Tunel 3x8m / 40x20mm | E6: 1 | F6: Телефон | G6: Телефон | H6: да | I6: Tilda | J6: s.mocnaszklarnia@profimetpl.com
A7: 2026-10-20 09:15 | B7: 11627047 | C7: +48513182410 | D7: Tunel 4x8m / 40x20mm 6mm | E7: 1 | F7: Google Ads | G7: Google Ads | H7: да | I7: Tilda | J7: script_Tilda_MOCNA
A8: 2026-10-20 09:12 | B8: bf6a1932 | C8: +48663029428 | E8: 1 | F8: Телефон | H8: нет
A9: 2026-10-20 05:38 | B9: 17933257 | C9: +48784426778 | D9: Tunel 3x4m / 40x20mm 6mm | E9: 1 | F9: Нет метки | G9: Нет метки | H9: да | I9: Tilda | J9: script_Tilda_MOCNA
A10: 2026-10-19 18:14 | B10: 19289642 | C10: +48663825755 | D10: Tunel 3x4m / 40x20mm | E10: 1 | F10: Нет метки | G10: Нет метки | H10: да | I10: Tilda | J10: script_Tilda_MOCNA
A11: 2026-10-19 13:02 | B11: fbe10701 | C11: +48889929886 | D11: Tunel 2,5x6m / 40x20mm 6mm | E11: 1 | F11: Телефон | G11: Телефон | H11: да | I11: Tilda | J11: profimet100@gmail.com
A12: 2026-10-19 12:32 | B12: aaedb304 | C12: +48600341180 | E12: 1 | F12: Телефон | H12: нет
A13: 2026-10-19 12:10 | B13: 7b7768bf | C13: +48785506010 | D13: Domek 2.5x4m / 40x20mm 6mm | E13: 1 | F13: Телефон | G13: Телефон | H13: да | I13: Tilda | J13: s.mocnaszklarnia@profimetpl.com
A14: 2026-10-19 11:31 | B14: a6f32d59 | C14: +48601487236 | D14: Tunel 2,5x4m / 40x20mm 6mm | E14: 1 | F14: Телефон | G14: Телефон | H14: да | I14: Tilda | J14: s.mocnaszklarnia@profimetpl.com
A15: 2026-10-19 09:07 | B15: 08eec9f5 | C15: +48694599397 | D15: Tunel 2x3m / 20x20mm | E15: 1 | F15: Телефон | G15: Телефон | H15: да | I15: Tilda | J15: profimet100@gmail.com
A16: 2026-10-19 09:00 | B16: 11122103 | C16: +48575880187 | D16: Tunel 3x6m / 40x20mm 6mm | E16: 1 | F16: Google Ads | G16: Google Ads | H16: да | I16: Tilda | J16: script_Tilda_MOCNA
A17: 2026-10-19 08:59 | B17: b80e1291 | C17: +48608210728 | D17: Tunel 3,5x8m / 40x20mm 6mm | E17: 1 | F17: Телефон | G17: Телефон | H17: да | I17: Tilda | J17: profimet100@gmail.com
A18: 2026-10-19 08:43 | B18: 87454299 | C18: +48697778816 | D18: Tunel 3x6m / 20x20mm 6mm | E18: 1 | F18: Google Ads | G18: Google Ads | H18: да | I18: Tilda | J18: script_Tilda_MOCNA
A19: 2026-10-19 06:53 | B19: 14152447 | C19: +48662587868 | D19: Tunel 3x4m / 40x20mm (D) 6mm | E19: 1 | F19: Google Ads | G19: Google Ads | H19: да | I19: Tilda | J19: script_Tilda_MOCNA
A20: 2026-10-18 13:15 | B20: 10412626 | C20: +48513124984 | D20: Tunel 3x6m / 40x20mm 6mm | E20: 1 | F20: Google Ads | G20: Google Ads | H20: да | I20: Tilda | J20: script_Tilda_MOCNA
A21: 2026-10-16 14:14 | B21: 19868832 | C21: +48661110820 | D21: Domek 2.5x4m / 40x20mm 6mm | E21: 1 | F21: Нет метки | G21: Нет метки | H21: да | I21: Tilda | J21: script_Tilda_MOCNA
A22: 2026-10-16 14:12 | B22: 13392213 | C22: +48515126940 | D22: Tunel 3,5x12m / 40x20mm 6mm | E22: 1 | F22: Нет метки | G22: Нет метки | H22: да | I22: Tilda | J22: script_Tilda_MOCNA
A23: 2026-10-16 12:54 | B23: 5edff5a1 | C23: +48691603750 | D23: Tunel 3x6m / 40x20mm 6mm | E23: 1 | F23: Телефон | G23: Телефон | H23: да | I23: Tilda | J23: m.mocnaszklarnia@profimetpl.com
A24: 2026-10-16 12:49 | B24: 20eabe57 | C24: +48690189460 | D24: Tunel 3x4m / 40x20mm (D) | E24: 1 | F24: Телефон | G24: Телефон | H24: да | I24: Tilda | J24: s.mocnaszklarnia@profimetpl.com
... A30: 2026-10-15 16:37 | B30: 16762687 | C30: +48692461217 | D30: Tunel 3x6m / 40x20mm 6mm | E30: 1 | F30: Google Ads | G30: Google Ads | H30: да | I30: Tilda | J30: script_Tilda_MOCNA
A31: 2026-10-15 12:57 | B31: 64a90a4e | C31: +48888872004 | E31: 1 | F31: Телефон | H31: нет
A32: 2026-10-15 10:10 | B32: dd533b5b | C32: +48604540409 | D32: Tunel 3x3m / 40x20mm | E32: 1 | F32: Телефон | G32: Телефон | H32: да | I32: Tilda | J32: profimet100@gmail.com
A33: 2026-10-15 09:33 | B33: 16990507 | C33: +48696439151 | D33: Domek 2.5x6m / 40x20mm 6mm | E33: 1 | F33: Google Ads | G33: Google Ads | H33: да | I33: Tilda | J33: script_Tilda_MOCNA
A34: 2026-10-15 08:52 | B34: 778938e9 | C34: +48887806548 | D34: Tunel 3x6m / 40x20mm | E34: 1 | F34: Телефон | G34: Нет метки | H34: да | I34: Tilda | J34: m.mocnaszklarnia@profimetpl.com
A35: 2026-10-15 08:17 | B35: c04c84af | C35: +48665506506 | E35: 1 | F35: Телефон | H35: нет
A36: 2026-10-14 13:40 | B36: e688d054 | C36: +48793639219 | D36: Domek 2.5x4m / 40x20mm 6mm | E36: 1 | F36: Телефон | G36: Google Ads | H36: да | I36: Tilda | J36: profimet100@gmail.com
A37: 2026-10-14 11:19 | B37: 3dc2ad08 | C37: +48793793239 | D37: Tunel 3x4m / 40x20mm 6mm | E37: 1 | F37: Телефон | G37: Телефон | H37: да | I37: Tilda | J37: s.mocnaszklarnia@profimetpl.com
A38: 2026-10-14 11:15 | B38: d9e6d938 | C38: +48512967007 | D38: Tunel 3x4m / 40x20mm 6mm | E38: 1 | F38: Телефон | G38: Телефон | H38: да | I38: Tilda | J38: s.mocnaszklarnia@profimetpl.com
A39: 2026-10-14 09:47 | B39: 10776976 | C39: +48608583298 | D39: Tunel 3x4m / 40x20mm 6mm | E39: 1 | F39: Google Ads | G39: Google Ads | H39: да | I39: Tilda | J39: script_Tilda_MOCNA
A40: 2026-10-13 19:03 | B40: 14153391 | C40: +48511999585 | D40: Tunel 3x8m / 40x20mm (D) 6mm | E40: 1 | F40: Нет метки | G40: Нет метки | H40: да | I40: Tilda | J40: script_Tilda_MOCNA
A41: 2026-10-13 10:58 | B41: e89c2916 | C41: +48517906559 | D41: Domek 2,1x4m / 40x20mm 6mm | E41: 1 | F41: Телефон | G41: Телефон | H41: да | I41: Tilda | J41: s.mocnaszklarnia@profimetpl.com
A42: 2026-10-13 09:31 | B42: 15039088 | C42: +48782515538 | D42: Tunel 3x6m / 40x20mm 6mm | E42: 1 | F42: Google Ads | G42: Google Ads | H42: да | I42: Tilda | J42: script_Tilda_MOCNA
A43: 2026-10-13 09:13 | B43: 21052978 | C43: +48603672717 | D43: Tunel 3x4m / 40x20mm | E43: 1 | F43: Нет метки | G43: Нет метки | H43: да | I43: Tilda | J43: script_Tilda_MOCNA
A44: 2026-10-13 08:18 | B44: cfe9a9c4 | C44: +48600750668 | D44: Tunel 3x6m / 40x20mm 6mm | E44: 1 | F44: Телефон | G44: Телефон | H44: да | I44: Tilda | J44: m.mocnaszklarnia@profimetpl.com
A45: 2026-10-13 05:04 | B45: 20458306 | C45: +48500205871 | D45: Tunel 3x8m / 40x20mm | E45: 1 | F45: Google Ads | G45: Google Ads | H45: да | I45: Tilda | J45: script_Tilda_MOCNA
...

Sheet Расхождения
A1: Раздел | B1: Заказ | C1: Дата | D1: Источник у клиента | E1: Источник по правилу клиента | F1: Причина
A2: Есть у клиента, нет у нас | B2: 02b0adbd | C2: 2026-10-20 07:11 | D2: Нет метки | F2: Заказа с таким номером в выгрузке CRM нет, есть только обращения с этим телефоном
A3: Есть у клиента, нет у нас | B3: 0b7a7433 | C3: 2026-10-16 07:28 | D3: Нет метки | F3: Заказа с таким номером в выгрузке CRM нет, есть только обращения с этим телефоном
A4: Источник у клиента другой | B4: 778938e9 | C4: 2026-10-15 08:55 | D4: Нет метки | E4: Телефон | F4: Правило клиента даёт «Телефон», у клиента «Нет метки» (вероятно, менеджер выбрал источник вручную)
A5: Есть у клиента, нет у нас | B5: 3fa3d10e | C5: 2026-10-14 14:14 | D5: Телефон | F5: В выгрузке CRM нет ни заказа, ни обращений с этим телефоном
A6: Есть у клиента, нет у нас | B6: 6d5d24da | C6: 2026-10-14 14:13 | D6: Телефон | F6: В выгрузке CRM нет ни заказа, ни обращений с этим телефоном
A7: Источник у клиента другой | B7: e688d054 | C7: 2026-10-14 13:46 | D7: Google Ads | E7: Телефон | F7: Правило клиента даёт «Телефон», у клиента «Google Ads» (вероятно, менеджер выбрал источник вручную)
A8: Есть у клиента, нет у нас | B8: e8f4485a | C8: 2026-10-11 10:10 | D8: Нет метки | F8: Заказа с таким номером в выгрузке CRM нет, есть только обращения с этим телефоном
A9: Есть у клиента, нет у нас | B9: 13d731b9 | C9: 2026-10-07 14:20 | D9: Телефон | F9: В выгрузке CRM нет ни заказа, ни обращений с этим телефоном
A10: Источник у клиента другой | B10: b6188b62 | C10: 2026-10-06 10:28 | D10: Нет метки | E10: Телефон | F10: Правило клиента даёт «Телефон», у клиента «Нет метки» (вероятно, менеджер выбрал источник вручную)
A11: Источник у клиента другой | B11: 3c8a183d | C11: 2026-10-05 13:49 | D11: Нет метки | E11: Телефон | F11: Правило клиента даёт «Телефон», у клиента «Нет метки» (вероятно, менеджер выбрал источник вручную)
A12: Есть у нас, нет у клиента | B12: 18846728 | C12: 2026-10-06 17:56 | E12: Нет метки | F12: Причина неизвестна
A13: Есть у нас, нет у клиента | B13: 64a90a4e | C13: 2026-10-15 12:57 | E13: Телефон | F13: Повторная покупка: человек уже покупал раньше
A14: Есть у нас, нет у клиента | B14: 798061f6 | C14: 2026-10-06 09:27 | E14: Телефон | F14: Повторная покупка: человек уже покупал раньше
A15: Есть у нас, нет у клиента | B15: 7cd5d270 | C15: 2026-10-05 09:42 | E15: Телефон | F15: Причина неизвестна
A16: Есть у нас, нет у клиента | B16: aaedb304 | C16: 2026-10-19 12:32 | E16: Телефон | F16: Причина неизвестна
A17: Есть у нас, нет у клиента | B17: bf6a1932 | C17: 2026-10-20 09:12 | E17: Телефон | F17: Причина неизвестна
A18: Есть у нас, нет у клиента | B18: c04c84af | C18: 2026-10-15 08:17 | E18: Телефон | F18: Причина неизвестна
A19: Есть у нас, нет у клиента | B19: eb672196 | C19: 2026-10-05 00:00 | E19: Телефон | F19: Причина неизвестна
A20: Есть у нас, нет у клиента | B20: f7b9bc52 | C20: 2026-10-02 06:20 | E20: Телефон | F20: Повторная покупка: человек уже покупал раньше
